Task exception was never retrieved
future: <Task finished coro=<WebSocketCommonProtocol.send() done, defined at /usr/local/lib/python3.7/dist-packages/websockets/protocol.py:496> exception=ConnectionClosedOK('code = 1000 (OK), no reason')>
Traceback (most recent call last):
  File "/usr/local/lib/python3.7/dist-packages/websockets/protocol.py", line 530, in send
    await self.ensure_open()
  File "/usr/local/lib/python3.7/dist-packages/websockets/protocol.py", line 780, in ensure_open
    raise self.connection_closed_exc()
websockets.exceptions.ConnectionClosedOK: code = 1000 (OK), no reason
Task exception was never retrieved
future: <Task finished coro=<WebSocketCommonProtocol.send() done, defined at /usr/local/lib/python3.7/dist-packages/websockets/protocol.py:496> exception=ConnectionClosedOK('code = 1000 (OK), no reason')>
Traceback (most recent call last):
  File "/usr/local/lib/python3.7/dist-packages/websockets/protocol.py", line 530, in send
    await self.ensure_open()
  File "/usr/local/lib/python3.7/dist-packages/websockets/protocol.py", line 771, in ensure_open
    raise self.connection_closed_exc()
websockets.exceptions.ConnectionClosedOK: code = 1000 (OK), no reason
Task exception was never retrieved
future: <Task finished coro=<WebSocketCommonProtocol.send() done, defined at /usr/local/lib/python3.7/dist-packages/websockets/protocol.py:496> exception=ConnectionClosedOK('code = 1000 (OK), no reason')>
Traceback (most recent call last):
  File "/usr/local/lib/python3.7/dist-packages/websockets/protocol.py", line 530, in send
    await self.ensure_open()
  File "/usr/local/lib/python3.7/dist-packages/websockets/protocol.py", line 771, in ensure_open
    raise self.connection_closed_exc()
websockets.exceptions.ConnectionClosedOK: code = 1000 (OK), no reason
